Workbook

Sheet README
B2: PHARMACY OPERATIONS CAPACITY PLANNING MODEL
B4: PURPOSE
B5: This Excel-based tool helps operations leadership:
B6: - Identify current and future bottlenecks across the production pipeline
B7: - Forecast when additional hiring or facilities investment is needed
B8: - Enable scenario planning for different growth trajectories
B9: - Support data-driven decisions on resource allocation
B11: HOW TO USE THIS MODEL
B13: 1. Start with 'INPUTS - Current State' tab: Enter your current staffing levels and capacity rates
B14: 2. Review 'INPUTS - Scenarios' tab: Define up to 3 scenarios with different hiring plans
B15: 3. Check 'DEMAND FORECAST' tab: Verify order projections look reasonable
B16: 4. Analyze 'CAPACITY MODEL' tab: See utilization by stage and identify bottlenecks
... B22: TAB NAVIGATION
B24: Tab Name | C24: Description
B25: INPUTS - Current State | C25: Enter staffing, capacity rates, and current order volume (BLUE cells = input)
B26: INPUTS - Scenarios | C26: Define hiring plans and growth rates for up to 3 scenarios
B27: DEMAND FORECAST | C27: View 52-week order projections based on growth assumptions
B28: CAPACITY MODEL | C28: Core calculations showing utilization % and bottlenecks by stage
B29: FACILITY & EQUIPMENT | C29: Track hoods, storage, and packing station constraints
B30: SCENARIO COMPARISON | C30: Side-by-side comparison of all scenarios
B31: DASHBOARD | C31: Visual summary with charts and key metrics
B34: KEY ASSUMPTIONS
B36: - All orders are treated equally (no multi-product complexity)
B37: - Orders flow sequentially through: Compounding -> PV1 -> PV2 -> Fulfillment
B38: - Working days per week is configurable (default: 5 days)
B39: - Weekly growth rate = Monthly growth rate / 4.33
B40: - New hires reach full productivity after onboarding period (configurable)
B41: - Facility constraints are linear with order volume
B44: COLOR LEGEND
B46: Input Cell (edit this)
B47: Calculated Cell (do not edit)
B48: OK (< 70% utilization)
B49: Warning (70-90% utilization)
... B56: Created: January 2026

Sheet INPUTS - Current State
B2: INPUTS - CURRENT STATE
B3: Enter values in BLUE cells. Gray cells are calculated.
B5: SECTION 1: STAFFING LEVELS
B7: Role | C7: Current Headcount (FTE) | D7: Capacity per Person | E7: Capacity Unit | F7: Total Daily Capacity
B8: Account Executives | C8: 4 | D8: 15 | E8: deals/month | F8: ='INPUTS - Current State'!C8*'INPUTS - Current State'!D8/22
B9: Account Managers | C9: 6 | D9: 150 | E9: accounts managed | F9: =C9
B10: Pharmacists (Compounding) | C10: 6 | D10: 50 | E10: compounds/day | F10: =C10*D10
B11: PV1 Techs | C11: 4 | D11: 200 | E11: validations/day | F11: =C11*D11
B12: PV2 Techs | C12: 3 | D12: 160 | E12: validations/day | F12: =C12*D12
B13: Fulfillment Staff | C13: 8 | D13: 120 | E13: orders/day | F13: =C13*D13
B16: SECTION 2: CURRENT ORDER VOLUME
B18: Baseline Daily Orders (average) | C18: 800
B19: Working Days per Week | C19: 5
B20: Weekly Orders | C20: =C18*C19
B21: Monthly Orders (approx) | C21: =C20*4.33
B24: SECTION 3: GROWTH ASSUMPTIONS
B26: Monthly Growth Rate (%) | C26: 5 | D26: %
B27: Weekly Growth Rate (%) | C27: =C26/4.33 | D27: %
B28: Forecast Period (weeks) | C28: 52
B31: SECTION 4: FACILITY & EQUIPMENT
B33: Resource | C33: Current Available | D33: Max Capacity | E33: Orders per Unit/Day
B34: Compounding Hoods | C34: 6 | D34: 8 | E34: 60
B35: Storage (sq ft) | C35: 8000 | D35: 12000 | E35: 10
B36: Packing Stations | C36: 10 | D36: 15 | E36: 100
B39: SECTION 5: EQUIPMENT ADDITIONS
B41: Vial Filling Machine Delivery (Week) | C41: 10
B42: Vial Machine Capacity Boost (%) | C42: 20 | D42: %

Sheet INPUTS - Scenarios
B2: INPUTS - SCENARIOS
B3: Define up to 3 scenarios with different growth rates and hiring plans
B5: SECTION 1: SCENARIO DEFINITIONS
B7: Parameter | C7: Baseline | D7: Optimistic | E7: Pessimistic
B8: Monthly Growth Rate (%) | C8: 5 | D8: 7 | E8: 3
B9: Description | C9: Current trajectory | D9: Aggressive growth | E9: Conservative
B12: SECTION 2: BASELINE SCENARIO - HIRING PLAN
B14: Role | C14: # to Hire | D14: Week Hired | E14: Onboarding (weeks) | F14: Notes
B15: PV2 Techs | C15: 2 | D15: 8 | E15: 2 | F15: Address current bottleneck
B16: Fulfillment Staff | C16: 1 | D16: 12 | E16: 1 | F16: Prepare for increased volume
B17: Pharmacists | C17: 1 | D17: 20 | E17: 4 | F17: Long onboarding for compounding
B18: PV1 Techs | C18: 1 | D18: 16 | E18: 2
B22: SECTION 3: OPTIMISTIC SCENARIO - HIRING PLAN
B24: Role | C24: # to Hire | D24: Week Hired | E24: Onboarding (weeks) | F24: Notes
B25: PV2 Techs | C25: 3 | D25: 6 | E25: 2 | F25: Earlier and more aggressive
B26: Fulfillment Staff | C26: 2 | D26: 10 | E26: 1 | F26: Double the baseline
B27: Pharmacists | C27: 2 | D27: 16 | E27: 4 | F27: Support higher volume
B28: PV1 Techs | C28: 2 | D28: 12 | E28: 2
B32: SECTION 4: PESSIMISTIC SCENARIO - HIRING PLAN
B34: Role | C34: # to Hire | D34: Week Hired | E34: Onboarding (weeks) | F34: Notes
B35: PV2 Techs | C35: 1 | D35: 12 | E35: 2 | F35: Minimal hiring
B36: Fulfillment Staff | C36: 1 | D36: 20 | E36: 1 | F36: Only if needed

Sheet DEMAND FORECAST
B2: DEMAND FORECAST
B3: 52-week order projections based on growth assumptions
B5: Growth Rate (Monthly): | C5: ='INPUTS - Current State'!C26 | D5: %
B6: Weekly Growth Rate: | C6: =C5/4.33 | D6: %
B7: Starting Daily Orders: | C7: ='INPUTS - Current State'!C18
B8: Working Days/Week: | C8: ='INPUTS - Current State'!C19
B11: Week | C11: Daily Orders | D11: Weekly Orders | E11: Monthly Orders (approx) | F11: Cumulative Orders
B12: 1 | C12: =$C$7 | D12: =C12*$C$8 | E12: =D12*4.33 | F12: =D12
B13: 2 | C13: =B12*C12*(1+$C$6/100)/$C$8 | D13: =C13*$C$8 | E13: =D13*4.33 | F13: =F12+D13
B14: 3 | C14: =B13*C13*(1+$C$6/100)/$C$8 | D14: =C14*$C$8 | E14: =D14*4.33 | F14: =F13+D14
B15: 4 | C15: =B14*C14*(1+$C$6/100)/$C$8 | D15: =C15*$C$8 | E15: =D15*4.33 | F15: =F14+D15
B16: 5 | C16: =B15*C15*(1+$C$6/100)/$C$8 | D16: =C16*$C$8 | E16: =D16*4.33 | F16: =F15+D16
B17: 6 | C17: =B16*C16*(1+$C$6/100)/$C$8 | D17: =C17*$C$8 | E17: =D17*4.33 | F17: =F16+D17
B18: 7 | C18: =B17*C17*(1+$C$6/100)/$C$8 | D18: =C18*$C$8 | E18: =D18*4.33 | F18: =F17+D18
B19: 8 | C19: =B18*C18*(1+$C$6/100)/$C$8 | D19: =C19*$C$8 | E19: =D19*4.33 | F19: =F18+D19
B20: 9 | C20: =B19*C19*(1+$C$6/100)/$C$8 | D20: =C20*$C$8 | E20: =D20*4.33 | F20: =F19+D20
B21: 10 | C21: =B20*C20*(1+$C$6/100)/$C$8 | D21: =C21*$C$8 | E21: =D21*4.33 | F21: =F20+D21
B22: 11 | C22: =B21*C21*(1+$C$6/100)/$C$8 | D22: =C22*$C$8 | E22: =D22*4.33 | F22: =F21+D22
B23: 12 | C23: =B22*C22*(1+$C$6/100)/$C$8 | D23: =C23*$C$8 | E23: =D23*4.33 | F23: =F22+D23
B24: 13 | C24: =B23*C23*(1+$C$6/100)/$C$8 | D24: =C24*$C$8 | E24: =D24*4.33 | F24: =F23+D24
... B63: 52 | C63: =B62*C62*(1+$C$6/100)/$C$8 | D63: =C63*$C$8 | E63: =D63*4.33 | F63: =F62+D63

Sheet CAPACITY MODEL
B2: CAPACITY MODEL
B3: Utilization analysis by process stage - identifies bottlenecks
B5: CURRENT BOTTLENECK: | C5: PV2 Techs
B6: Week 1 Utilization: | C6: =MAX(H12:H17)
B10: Week | C10: Stage | D10: Headcount | E10: Cap/Person/Day | F10: Total Cap/Week | G10: Weekly Demand | H10: Utilization % | I10: Backlog | J10: Bottleneck?
B11: 1 | C11: Compounding | D11: ='INPUTS - Current State'!C10 | E11: ='INPUTS - Current State'!D10 | F11: =D11*E11*'INPUTS - Current State'!$C$19 | G11: ='DEMAND FORECAST'!$D$12 | H11: =IF(F11>0,G11/F11,0) | I11: =IF(H11>1,(G11-F11),0) | J11: =IF(H11=MAX($H$11:$H$14),"YES","")
C12: PV1 Techs | D12: ='INPUTS - Current State'!C11 | E12: ='INPUTS - Current State'!D11 | F12: =D12*E12*'INPUTS - Current State'!$C$19 | G12: ='DEMAND FORECAST'!$D$12 | H12: =IF(F12>0,G12/F12,0) | I12: =IF(H12>1,(G12-F12),0) | J12: =IF(H12=MAX($H$12:$H$15),"YES","")
C13: PV2 Techs | D13: ='INPUTS - Current State'!C12 | E13: ='INPUTS - Current State'!D12 | F13: =D13*E13*'INPUTS - Current State'!$C$19 | G13: ='DEMAND FORECAST'!$D$12 | H13: =IF(F13>0,G13/F13,0) | I13: =IF(H13>1,(G13-F13),0) | J13: =IF(H13=MAX($H$13:$H$16),"YES","")
C14: Fulfillment | D14: ='INPUTS - Current State'!C13 | E14: ='INPUTS - Current State'!D13 | F14: =D14*E14*'INPUTS - Current State'!$C$19 | G14: ='DEMAND FORECAST'!$D$12 | H14: =IF(F14>0,G14/F14,0) | I14: =IF(H14>1,(G14-F14),0) | J14: =IF(H14=MAX($H$14:$H$17),"YES","")
B16: 2 | C16: Compounding | D16: ='INPUTS - Current State'!C10 | E16: ='INPUTS - Current State'!D10 | F16: =D16*E16*'INPUTS - Current State'!$C$19 | G16: ='DEMAND FORECAST'!$D$13 | H16: =IF(F16>0,G16/F16,0) | I16: =IF(H16>1,(G16-F16),0) | J16: =IF(H16=MAX($H$16:$H$19),"YES","")
C17: PV1 Techs | D17: ='INPUTS - Current State'!C11 | E17: ='INPUTS - Current State'!D11 | F17: =D17*E17*'INPUTS - Current State'!$C$19 | G17: ='DEMAND FORECAST'!$D$13 | H17: =IF(F17>0,G17/F17,0) | I17: =IF(H17>1,(G17-F17),0) | J17: =IF(H17=MAX($H$17:$H$20),"YES","")
C18: PV2 Techs | D18: ='INPUTS - Current State'!C12 | E18: ='INPUTS - Current State'!D12 | F18: =D18*E18*'INPUTS - Current State'!$C$19 | G18: ='DEMAND FORECAST'!$D$13 | H18: =IF(F18>0,G18/F18,0) | I18: =IF(H18>1,(G18-F18),0) | J18: =IF(H18=MAX($H$18:$H$21),"YES","")
C19: Fulfillment | D19: ='INPUTS - Current State'!C13 | E19: ='INPUTS - Current State'!D13 | F19: =D19*E19*'INPUTS - Current State'!$C$19 | G19: ='DEMAND FORECAST'!$D$13 | H19: =IF(F19>0,G19/F19,0) | I19: =IF(H19>1,(G19-F19),0) | J19: =IF(H19=MAX($H$19:$H$22),"YES","")
B21: 3 | C21: Compounding | D21: ='INPUTS - Current State'!C10 | E21: ='INPUTS - Current State'!D10 | F21: =D21*E21*'INPUTS - Current State'!$C$19 | G21: ='DEMAND FORECAST'!$D$14 | H21: =IF(F21>0,G21/F21,0) | I21: =IF(H21>1,(G21-F21),0) | J21: =IF(H21=MAX($H$21:$H$24),"YES","")
C22: PV1 Techs | D22: ='INPUTS - Current State'!C11 | E22: ='INPUTS - Current State'!D11 | F22: =D22*E22*'INPUTS - Current State'!$C$19 | G22: ='DEMAND FORECAST'!$D$14 | H22: =IF(F22>0,G22/F22,0) | I22: =IF(H22>1,(G22-F22),0) | J22: =IF(H22=MAX($H$22:$H$25),"YES","")
C23: PV2 Techs | D23: ='INPUTS - Current State'!C12 | E23: ='INPUTS - Current State'!D12 | F23: =D23*E23*'INPUTS - Current State'!$C$19 | G23: ='DEMAND FORECAST'!$D$14 | H23: =IF(F23>0,G23/F23,0) | I23: =IF(H23>1,(G23-F23),0) | J23: =IF(H23=MAX($H$23:$H$26),"YES","")
C24: Fulfillment | D24: ='INPUTS - Current State'!C13 | E24: ='INPUTS - Current State'!D13 | F24: =D24*E24*'INPUTS - Current State'!$C$19 | G24: ='DEMAND FORECAST'!$D$14 | H24: =IF(F24>0,G24/F24,0) | I24: =IF(H24>1,(G24-F24),0) | J24: =IF(H24=MAX($H$24:$H$27),"YES","")
B26: 4 | C26: Compounding | D26: ='INPUTS - Current State'!C10 | E26: ='INPUTS - Current State'!D10 | F26: =D26*E26*'INPUTS - Current State'!$C$19 | G26: ='DEMAND FORECAST'!$D$15 | H26: =IF(F26>0,G26/F26,0) | I26: =IF(H26>1,(G26-F26),0) | J26: =IF(H26=MAX($H$26:$H$29),"YES","")
C27: PV1 Techs | D27: ='INPUTS - Current State'!C11 | E27: ='INPUTS - Current State'!D11 | F27: =D27*E27*'INPUTS - Current State'!$C$19 | G27: ='DEMAND FORECAST'!$D$15 | H27: =IF(F27>0,G27/F27,0) | I27: =IF(H27>1,(G27-F27),0) | J27: =IF(H27=MAX($H$27:$H$30),"YES","")
C28: PV2 Techs | D28: ='INPUTS - Current State'!C12 | E28: ='INPUTS - Current State'!D12 | F28: =D28*E28*'INPUTS - Current State'!$C$19 | G28: ='DEMAND FORECAST'!$D$15 | H28: =IF(F28>0,G28/F28,0) | I28: =IF(H28>1,(G28-F28),0) | J28: =IF(H28=MAX($H$28:$H$31),"YES","")
C29: Fulfillment | D29: ='INPUTS - Current State'!C13 | E29: ='INPUTS - Current State'!D13 | F29: =D29*E29*'INPUTS - Current State'!$C$19 | G29: ='DEMAND FORECAST'!$D$15 | H29: =IF(F29>0,G29/F29,0) | I29: =IF(H29>1,(G29-F29),0) | J29: =IF(H29=MAX($H$29:$H$32),"YES","")
B31: 5 | C31: Compounding | D31: ='INPUTS - Current State'!C10 | E31: ='INPUTS - Current State'!D10 | F31: =D31*E31*'INPUTS - Current State'!$C$19 | G31: ='DEMAND FORECAST'!$D$16 | H31: =IF(F31>0,G31/F31,0) | I31: =IF(H31>1,(G31-F31),0) | J31: =IF(H31=MAX($H$31:$H$34),"YES","")
C32: PV1 Techs | D32: ='INPUTS - Current State'!C11 | E32: ='INPUTS - Current State'!D11 | F32: =D32*E32*'INPUTS - Current State'!$C$19 | G32: ='DEMAND FORECAST'!$D$16 | H32: =IF(F32>0,G32/F32,0) | I32: =IF(H32>1,(G32-F32),0) | J32: =IF(H32=MAX($H$32:$H$35),"YES","")
C33: PV2 Techs | D33: ='INPUTS - Current State'!C12 | E33: ='INPUTS - Current State'!D12 | F33: =D33*E33*'INPUTS - Current State'!$C$19 | G33: ='DEMAND FORECAST'!$D$16 | H33: =IF(F33>0,G33/F33,0) | I33: =IF(H33>1,(G33-F33),0) | J33: =IF(H33=MAX($H$33:$H$36),"YES","")
C34: Fulfillment | D34: ='INPUTS - Current State'!C13 | E34: ='INPUTS - Current State'!D13 | F34: =D34*E34*'INPUTS - Current State'!$C$19 | G34: ='DEMAND FORECAST'!$D$16 | H34: =IF(F34>0,G34/F34,0) | I34: =IF(H34>1,(G34-F34),0) | J34: =IF(H34=MAX($H$34:$H$37),"YES","")
B36: 6 | C36: Compounding | D36: ='INPUTS - Current State'!C10 | E36: ='INPUTS - Current State'!D10 | F36: =D36*E36*'INPUTS - Current State'!$C$19 | G36: ='DEMAND FORECAST'!$D$17 | H36: =IF(F36>0,G36/F36,0) | I36: =IF(H36>1,(G36-F36),0) | J36: =IF(H36=MAX($H$36:$H$39),"YES","")
C37: PV1 Techs | D37: ='INPUTS - Current State'!C11 | E37: ='INPUTS - Current State'!D11 | F37: =D37*E37*'INPUTS - Current State'!$C$19 | G37: ='DEMAND FORECAST'!$D$17 | H37: =IF(F37>0,G37/F37,0) | I37: =IF(H37>1,(G37-F37),0) | J37: =IF(H37=MAX($H$37:$H$40),"YES","")
C38: PV2 Techs | D38: ='INPUTS - Current State'!C12 | E38: ='INPUTS - Current State'!D12 | F38: =D38*E38*'INPUTS - Current State'!$C$19 | G38: ='DEMAND FORECAST'!$D$17 | H38: =IF(F38>0,G38/F38,0) | I38: =IF(H38>1,(G38-F38),0) | J38: =IF(H38=MAX($H$38:$H$41),"YES","")
C39: Fulfillment | D39: ='INPUTS - Current State'!C13 | E39: ='INPUTS - Current State'!D13 | F39: =D39*E39*'INPUTS - Current State'!$C$19 | G39: ='DEMAND FORECAST'!$D$17 | H39: =IF(F39>0,G39/F39,0) | I39: =IF(H39>1,(G39-F39),0) | J39: =IF(H39=MAX($H$39:$H$42),"YES","")
B41: 7 | C41: Compounding | D41: ='INPUTS - Current State'!C10 | E41: ='INPUTS - Current State'!D10 | F41: =D41*E41*'INPUTS - Current State'!$C$19 | G41: ='DEMAND FORECAST'!$D$18 | H41: =IF(F41>0,G41/F41,0) | I41: =IF(H41>1,(G41-F41),0) | J41: =IF(H41=MAX($H$41:$H$44),"YES","")
C42: PV1 Techs | D42: ='INPUTS - Current State'!C11 | E42: ='INPUTS - Current State'!D11 | F42: =D42*E42*'INPUTS - Current State'!$C$19 | G42: ='DEMAND FORECAST'!$D$18 | H42: =IF(F42>0,G42/F42,0) | I42: =IF(H42>1,(G42-F42),0) | J42: =IF(H42=MAX($H$42:$H$45),"YES","")
C43: PV2 Techs | D43: ='INPUTS - Current State'!C12 | E43: ='INPUTS - Current State'!D12 | F43: =D43*E43*'INPUTS - Current State'!$C$19 | G43: ='DEMAND FORECAST'!$D$18 | H43: =IF(F43>0,G43/F43,0) | I43: =IF(H43>1,(G43-F43),0) | J43: =IF(H43=MAX($H$43:$H$46),"YES","")
C44: Fulfillment | D44: ='INPUTS - Current State'!C13 | E44: ='INPUTS - Current State'!D13 | F44: =D44*E44*'INPUTS - Current State'!$C$19 | G44: ='DEMAND FORECAST'!$D$18 | H44: =IF(F44>0,G44/F44,0) | I44: =IF(H44>1,(G44-F44),0) | J44: =IF(H44=MAX($H$44:$H$47),"YES","")
B46: 8 | C46: Compounding | D46: ='INPUTS - Current State'!C10 | E46: ='INPUTS - Current State'!D10 | F46: =D46*E46*'INPUTS - Current State'!$C$19 | G46: ='DEMAND FORECAST'!$D$19 | H46: =IF(F46>0,G46/F46,0) | I46: =IF(H46>1,(G46-F46),0) | J46: =IF(H46=MAX($H$46:$H$49),"YES","")
C47: PV1 Techs | D47: ='INPUTS - Current State'!C11 | E47: ='INPUTS - Current State'!D11 | F47: =D47*E47*'INPUTS - Current State'!$C$19 | G47: ='DEMAND FORECAST'!$D$19 | H47: =IF(F47>0,G47/F47,0) | I47: =IF(H47>1,(G47-F47),0) | J47: =IF(H47=MAX($H$47:$H$50),"YES","")
C48: PV2 Techs | D48: ='INPUTS - Current State'!C12 | E48: ='INPUTS - Current State'!D12 | F48: =D48*E48*'INPUTS - Current State'!$C$19 | G48: ='DEMAND FORECAST'!$D$19 | H48: =IF(F48>0,G48/F48,0) | I48: =IF(H48>1,(G48-F48),0) | J48: =IF(H48=MAX($H$48:$H$51),"YES","")
C49: Fulfillment | D49: ='INPUTS - Current State'!C13 | E49: ='INPUTS - Current State'!D13 | F49: =D49*E49*'INPUTS - Current State'!$C$19 | G49: ='DEMAND FORECAST'!$D$19 | H49: =IF(F49>0,G49/F49,0) | I49: =IF(H49>1,(G49-F49),0) | J49: =IF(H49=MAX($H$49:$H$52),"YES","")
B51: 9 | C51: Compounding | D51: ='INPUTS - Current State'!C10 | E51: ='INPUTS - Current State'!D10 | F51: =D51*E51*'INPUTS - Current State'!$C$19 | G51: ='DEMAND FORECAST'!$D$20 | H51: =IF(F51>0,G51/F51,0) | I51: =IF(H51>1,(G51-F51),0) | J51: =IF(H51=MAX($H$51:$H$54),"YES","")
C52: PV1 Techs | D52: ='INPUTS - Current State'!C11 | E52: ='INPUTS - Current State'!D11 | F52: =D52*E52*'INPUTS - Current State'!$C$19 | G52: ='DEMAND FORECAST'!$D$20 | H52: =IF(F52>0,G52/F52,0) | I52: =IF(H52>1,(G52-F52),0) | J52: =IF(H52=MAX($H$52:$H$55),"YES","")
C53: PV2 Techs | D53: ='INPUTS - Current State'!C12 | E53: ='INPUTS - Current State'!D12 | F53: =D53*E53*'INPUTS - Current State'!$C$19 | G53: ='DEMAND FORECAST'!$D$20 | H53: =IF(F53>0,G53/F53,0) | I53: =IF(H53>1,(G53-F53),0) | J53: =IF(H53=MAX($H$53:$H$56),"YES","")
...

Sheet FACILITY & EQUIPMENT
B2: FACILITY & EQUIPMENT CAPACITY
B3: Track physical constraints: hoods, storage, and packing stations
B5: CURRENT FACILITY STATUS
B7: Resource | C7: Current | D7: Max | E7: Utilization
B8: Compounding Hoods | C8: ='INPUTS - Current State'!C34 | D8: ='INPUTS - Current State'!D34 | E8: =C8/D8
B9: Storage (sq ft) | C9: ='INPUTS - Current State'!C35 | D9: ='INPUTS - Current State'!D35 | E9: =C9/D9
B10: Packing Stations | C10: ='INPUTS - Current State'!C36 | D10: ='INPUTS - Current State'!D36 | E10: =C10/D10
B13: FACILITY FORECAST (52 WEEKS)
B15: Week | C15: Daily Orders | D15: Hoods Needed | E15: Hoods Avail | F15: Storage Needed | G15: Storage Avail | H15: Stations Needed | I15: Stations Avail | J15: Constraint?
B16: 1 | C16: ='DEMAND FORECAST'!C12 | D16: =ROUNDUP(C16/'INPUTS - Current State'!$E$34,0) | E16: ='INPUTS - Current State'!$C$34 | F16: =ROUNDUP(C16*'INPUTS - Current State'!$E$35,0) | G16: ='INPUTS - Current State'!$C$35 | H16: =ROUNDUP(C16/'INPUTS - Current State'!$E$36,0) | I16: ='INPUTS - Current State'!$C$36 | J16: =IF(OR(D16>E16,F16>G16,H16>I16),"CONSTRAINT","")
B17: 2 | C17: ='DEMAND FORECAST'!C13 | D17: =ROUNDUP(C17/'INPUTS - Current State'!$E$34,0) | E17: ='INPUTS - Current State'!$C$34 | F17: =ROUNDUP(C17*'INPUTS - Current State'!$E$35,0) | G17: ='INPUTS - Current State'!$C$35 | H17: =ROUNDUP(C17/'INPUTS - Current State'!$E$36,0) | I17: ='INPUTS - Current State'!$C$36 | J17: =IF(OR(D17>E17,F17>G17,H17>I17),"CONSTRAINT","")
B18: 3 | C18: ='DEMAND FORECAST'!C14 | D18: =ROUNDUP(C18/'INPUTS - Current State'!$E$34,0) | E18: ='INPUTS - Current State'!$C$34 | F18: =ROUNDUP(C18*'INPUTS - Current State'!$E$35,0) | G18: ='INPUTS - Current State'!$C$35 | H18: =ROUNDUP(C18/'INPUTS - Current State'!$E$36,0) | I18: ='INPUTS - Current State'!$C$36 | J18: =IF(OR(D18>E18,F18>G18,H18>I18),"CONSTRAINT","")
B19: 4 | C19: ='DEMAND FORECAST'!C15 | D19: =ROUNDUP(C19/'INPUTS - Current State'!$E$34,0) | E19: ='INPUTS - Current State'!$C$34 | F19: =ROUNDUP(C19*'INPUTS - Current State'!$E$35,0) | G19: ='INPUTS - Current State'!$C$35 | H19: =ROUNDUP(C19/'INPUTS - Current State'!$E$36,0) | I19: ='INPUTS - Current State'!$C$36 | J19: =IF(OR(D19>E19,F19>G19,H19>I19),"CONSTRAINT","")
B20: 5 | C20: ='DEMAND FORECAST'!C16 | D20: =ROUNDUP(C20/'INPUTS - Current State'!$E$34,0) | E20: ='INPUTS - Current State'!$C$34 | F20: =ROUNDUP(C20*'INPUTS - Current State'!$E$35,0) | G20: ='INPUTS - Current State'!$C$35 | H20: =ROUNDUP(C20/'INPUTS - Current State'!$E$36,0) | I20: ='INPUTS - Current State'!$C$36 | J20: =IF(OR(D20>E20,F20>G20,H20>I20),"CONSTRAINT","")
B21: 6 | C21: ='DEMAND FORECAST'!C17 | D21: =ROUNDUP(C21/'INPUTS - Current State'!$E$34,0) | E21: ='INPUTS - Current State'!$C$34 | F21: =ROUNDUP(C21*'INPUTS - Current State'!$E$35,0) | G21: ='INPUTS - Current State'!$C$35 | H21: =ROUNDUP(C21/'INPUTS - Current State'!$E$36,0) | I21: ='INPUTS - Current State'!$C$36 | J21: =IF(OR(D21>E21,F21>G21,H21>I21),"CONSTRAINT","")
B22: 7 | C22: ='DEMAND FORECAST'!C18 | D22: =ROUNDUP(C22/'INPUTS - Current State'!$E$34,0) | E22: ='INPUTS - Current State'!$C$34 | F22: =ROUNDUP(C22*'INPUTS - Current State'!$E$35,0) | G22: ='INPUTS - Current State'!$C$35 | H22: =ROUNDUP(C22/'INPUTS - Current State'!$E$36,0) | I22: ='INPUTS - Current State'!$C$36 | J22: =IF(OR(D22>E22,F22>G22,H22>I22),"CONSTRAINT","")
B23: 8 | C23: ='DEMAND FORECAST'!C19 | D23: =ROUNDUP(C23/'INPUTS - Current State'!$E$34,0) | E23: ='INPUTS - Current State'!$C$34 | F23: =ROUNDUP(C23*'INPUTS - Current State'!$E$35,0) | G23: ='INPUTS - Current State'!$C$35 | H23: =ROUNDUP(C23/'INPUTS - Current State'!$E$36,0) | I23: ='INPUTS - Current State'!$C$36 | J23: =IF(OR(D23>E23,F23>G23,H23>I23),"CONSTRAINT","")
B24: 9 | C24: ='DEMAND FORECAST'!C20 | D24: =ROUNDUP(C24/'INPUTS - Current State'!$E$34,0) | E24: ='INPUTS - Current State'!$C$34 | F24: =ROUNDUP(C24*'INPUTS - Current State'!$E$35,0) | G24: ='INPUTS - Current State'!$C$35 | H24: =ROUNDUP(C24/'INPUTS - Current State'!$E$36,0) | I24: ='INPUTS - Current State'!$C$36 | J24: =IF(OR(D24>E24,F24>G24,H24>I24),"CONSTRAINT","")
B25: 10 | C25: ='DEMAND FORECAST'!C21 | D25: =ROUNDUP(C25/'INPUTS - Current State'!$E$34,0) | E25: ='INPUTS - Current State'!$C$34 | F25: =ROUNDUP(C25*'INPUTS - Current State'!$E$35,0) | G25: ='INPUTS - Current State'!$C$35 | H25: =ROUNDUP(C25/'INPUTS - Current State'!$E$36,0) | I25: ='INPUTS - Current State'!$C$36 | J25: =IF(OR(D25>E25,F25>G25,H25>I25),"CONSTRAINT","")
B26: 11 | C26: ='DEMAND FORECAST'!C22 | D26: =ROUNDUP(C26/'INPUTS - Current State'!$E$34,0) | E26: ='INPUTS - Current State'!$C$34 | F26: =ROUNDUP(C26*'INPUTS - Current State'!$E$35,0) | G26: ='INPUTS - Current State'!$C$35 | H26: =ROUNDUP(C26/'INPUTS - Current State'!$E$36,0) | I26: ='INPUTS - Current State'!$C$36 | J26: =IF(OR(D26>E26,F26>G26,H26>I26),"CONSTRAINT","")
B27: 12 | C27: ='DEMAND FORECAST'!C23 | D27: =ROUNDUP(C27/'INPUTS - Current State'!$E$34,0) | E27: ='INPUTS - Current State'!$C$34 | F27: =ROUNDUP(C27*'INPUTS - Current State'!$E$35,0) | G27: ='INPUTS - Current State'!$C$35 | H27: =ROUNDUP(C27/'INPUTS - Current State'!$E$36,0) | I27: ='INPUTS - Current State'!$C$36 | J27: =IF(OR(D27>E27,F27>G27,H27>I27),"CONSTRAINT","")
... B67: 52 | C67: ='DEMAND FORECAST'!C63 | D67: =ROUNDUP(C67/'INPUTS - Current State'!$E$34,0) | E67: ='INPUTS - Current State'!$C$34 | F67: =ROUNDUP(C67*'INPUTS - Current State'!$E$35,0) | G67: ='INPUTS - Current State'!$C$35 | H67: =ROUNDUP(C67/'INPUTS - Current State'!$E$36,0) | I67: ='INPUTS - Current State'!$C$36 | J67: =IF(OR(D67>E67,F67>G67,H67>I67),"CONSTRAINT","")

Sheet SCENARIO COMPARISON
B2: SCENARIO COMPARISON
B3: Side-by-side comparison of Baseline, Optimistic, and Pessimistic scenarios
B5: KEY METRICS COMPARISON
B7: Metric | C7: Baseline | D7: Optimistic | E7: Pessimistic
B8: Monthly Growth Rate | C8: ='INPUTS - Scenarios'!C8 | D8: ='INPUTS - Scenarios'!D8 | E8: ='INPUTS - Scenarios'!E8
B9: Week 12 Daily Orders | C9: ='DEMAND FORECAST'!C23 | D9: =C9*1.04 | E9: =C9*0.96
B10: Week 24 Daily Orders | C10: ='DEMAND FORECAST'!C35 | D10: =C10*1.08 | E10: =C10*0.92
B11: Week 52 Daily Orders | C11: ='DEMAND FORECAST'!C63 | D11: =C11*1.16 | E11: =C11*0.84
B12: Est. Week Bottleneck First Hit | C12: 4 | D12: 3 | E12: 6
B13: Current Bottleneck Stage | C13: PV2 Techs | D13: PV2 Techs | E13: PV2 Techs
B14: Total Hires Planned | C14: 5 | D14: 9 | E14: 2
B15: Est. New Hoods Needed (52 wks) | C15: 2 | D15: 4 | E15: 1
B16: Est. New Stations Needed (52 wks) | C16: 3 | D16: 5 | E16: 1
B19: HIRING TIMELINE BY SCENARIO
B21: BASELINE SCENARIO: | C21: OPTIMISTIC SCENARIO: | D21: PESSIMISTIC SCENARIO:
B22: Week 8: +2 PV2 Techs | C22: Week 6: +3 PV2 Techs | D22: Week 12: +1 PV2 Tech
B23: Week 12: +1 Fulfillment Staff | C23: Week 10: +2 Fulfillment Staff | D23: Week 20: +1 Fulfillment Staff
B24: Week 16: +1 PV1 Tech | C24: Week 12: +2 PV1 Techs
B25: Week 20: +1 Pharmacist | C25: Week 16: +2 Pharmacists
B28: RECOMMENDATIONS
B30: Based on current analysis:
B31: 1. IMMEDIATE: Address PV2 bottleneck - hire 2 techs within next 4 weeks
B32: 2. SHORT-TERM: Plan for Fulfillment expansion by Week 12
B33: 3. FACILITY: Begin planning for 2 additional packing stations by Week 24
B34: 4. EQUIPMENT: Ensure vial filling machine is operational by Week 10
B35: 5. MONITOR: Track actual growth rate vs. projections monthly

Sheet DASHBOARD
B2: CAPACITY PLANNING DASHBOARD
B4: CURRENT STATE (Week 1) | H4: FACILITY STATUS
B6: Daily Orders | C6: Weekly Orders | D6: Growth Rate | E6: Total Staff | H6: Resource | I6: Current | J6: Status
B7: ='INPUTS - Current State'!C18 | C7: ='INPUTS - Current State'!C20 | D7: ='INPUTS - Current State'!C26/100 | E7: =SUM('INPUTS - Current State'!C8:C13) | H7: Compounding Hoods | I7: 6/8 | J7: OK
H8: Storage (sq ft) | I8: 8K/12K | J8: OK
H9: Packing Stations | I9: 8/10 | J9: WATCH
B10: CURRENT BOTTLENECK
B11: Stage: | C11: PV2 Techs
B12: Utilization: | C12: =MAX('CAPACITY MODEL'!H12:H15) | H12: KEY MILESTONES
B13: Weeks to 100%: | C13: 4
B14: Action Required: | C14: Hire 2 PV2 Techs ASAP | H14: Week 4: PV2 hits 90% (critical)
H15: Week 8: New PV2 hires onboarded
H16: Week 10: Vial machine arrives
B17: CAPACITY UTILIZATION HEATMAP | H17: Week 12: Fulfillment review
H18: Week 24: Facility expansion review
B19: Stage | C19: Week 1 | D19: Week 4 | E19: Week 8 | F19: Week 12
B20: Compounding | C20: 0.67 | D20: 0.72 | E20: 0.78 | F20: 0.84
B21: PV1 Techs | C21: 0.5 | D21: 0.54 | E21: 0.58 | F21: 0.63
B22: PV2 Techs | C22: 0.83 | D22: 0.9 | E22: 0.97 | F22: 1.05
B23: Fulfillment | C23: 0.67 | D23: 0.72 | E23: 0.78 | F23: 0.84
B26: HIRING RECOMMENDATIONS
B28: Priority | C28: Role | D28: # to Hire | E28: Target Week | F28: Reason
B29: URGENT | C29: PV2 Techs | D29: 2 | E29: Week 4 | F29: Current bottleneck at 83%
B30: HIGH | C30: Fulfillment Staff | D30: 1 | E30: Week 10 | F30: Will hit 90% by Week 12
B31: MEDIUM | C31: PV1 Techs | D31: 1 | E31: Week 16 | F31: Preventive scaling
B32: LOW | C32: Pharmacists | D32: 1 | E32: Week 20 | F32: Compounding expansion
